<mujoco model="schunk_svh">
  <compiler angle="radian"/>

  <asset>
    <texture type="skybox" builtin="gradient" rgb1="0.9 0.9 0.9" rgb2="0.5 0.5 0.5" width="512" height="512"/>
    <texture name="texplane" type="2d" builtin="checker" rgb1=".25 .25 .25" rgb2=".3 .3 .3" width="512" height="512" mark="cross" markrgb=".8 .8 .8"/>
    <material name="matplane" reflectance="0.2" texture="texplane" texrepeat="1 1" texuniform="true"/>
    <material name="joint_part1" rgba="0.525 0.713 0.662 1.0"/>
    <material name="joint_part2" rgba="0.462 0.196 0.411 1.0"/>
    <material name="base" rgba="0.956863 0.796078 0.631373 1.0"/>
    <material name="tip" rgba="0.956 0.450 0.243 1.0"/>
    <material name="link1" rgba="0.949 0.631 0.823 1.0"/>
    <material name="link2" rgba="0.133 0.827 0.435 1.0"/>
    <material name="link3" rgba="0.968 0.721 0.313 1.0"/>
    <material name="link4" rgba="0.52549 0.529412 0.647059 1.0"/>
    <material name="link5" rgba="0.478431 0.415686 0.662745 1.0"/>
    <material name="link6" rgba="0.988 0.580 0.450 1.0"/>

    <mesh name="base10" file="base10.stl"/>
    <mesh name="h10" file="h10.stl"/>
    <mesh name="h11" file="h11.stl"/>
    <mesh name="d10" file="d10.stl"/>
    <mesh name="d11" file="d11.stl"/>
    <mesh name="d12" file="d12.stl"/>
    <mesh name="d13" file="d13.stl"/>
    <mesh name="f10" file="f10.stl"/>
    <mesh name="f11" file="f11.stl"/>
    <mesh name="f12" file="f12.stl"/>
    <mesh name="f13" file="f13.stl"/>
    <mesh name="f20" file="f20.stl"/>
    <mesh name="f21" file="f21.stl"/>
    <mesh name="f22" file="f22.stl"/>
    <mesh name="f23" file="f23.stl"/>
    <mesh name="f30" file="f30.stl"/>
    <mesh name="f31" file="f31.stl"/>
    <mesh name="f32" file="f32.stl"/>
    <mesh name="f33" file="f33.stl"/>
    <mesh name="f40" file="f40.stl"/>
    <mesh name="f41" file="f41.stl"/>
    <mesh name="f42" file="f42.stl"/>
    <mesh name="f43" file="f43.stl"/>
  </asset>

  <worldbody>
    <geom type="mesh" contype="0" conaffinity="0" group="1" density="0" mesh="base10"/>
    <geom type="mesh" mesh="base10"/>
    <geom type="mesh" contype="0" conaffinity="0" group="1" density="0" mesh="h10"/>
    <geom type="mesh" mesh="h10"/>
    <geom pos="-1.27248e-06 -0.02634 0.110001" quat="0.500048 0.499952 -0.5 0.5" type="mesh" contype="0" conaffinity="0" group="1" density="0" mesh="f20"/>
    <geom pos="-1.27248e-06 -0.02634 0.110001" quat="0.500048 0.499952 -0.5 0.5" type="mesh" mesh="f20"/>
    <geom pos="0.0177 -0.00713 0.02748" quat="1 0 0 0" type="mesh" contype="0" conaffinity="0" group="1" density="0" mesh="h11"/>
    <geom pos="0.0177 -0.00713 0.02748" quat="1 0 0 0" type="mesh" mesh="h11"/>
    <body name="Right_Hand_z" pos="-0.0169 0.01313 0" quat="0.700986 -0.0923056 0.0922868 0.701129">
      <inertial pos="0 0.00178276 0.162822" quat="0.70685 0.0190682 -0.0190682 0.70685" mass="0.0839" diaginertia="0.00280708 0.00218508 0.002108"/>
      <joint name="Right_Hand_Thumb_Opposition" pos="0 0 0" axis="0 0 -1" range="0 0.9879" actuatorfrcrange="-1000 1000"/>
      <geom pos="0 0 0.02442" quat="1 0 0 0" type="mesh" contype="0" conaffinity="0" group="1" density="0" mesh="d10"/>
      <geom pos="0 0 0.02442" quat="1 0 0 0" type="mesh" mesh="d10"/>
      <body name="Right_Hand_a" pos="0 0 0.04596" quat="0.329798 0.625462 0.329771 0.625525">
        <inertial pos="0.240205 0.010733 0.00019" quat="0.0202941 0.706815 -0.0202941 0.706815" mass="0.41222" diaginertia="0.01796 0.016832 0.00408805"/>
        <joint name="Right_Hand_Thumb_Flexion" pos="0 0 0" axis="0 0 1" range="0 0.9704" actuatorfrcrange="-1000 1000"/>
        <geom type="mesh" contype="0" conaffinity="0" group="1" density="0" mesh="d11"/>
        <geom type="mesh" mesh="d11"/>
        <body name="Right_Hand_b" pos="0.0485 0 0">
          <inertial pos="0.123157 -0.008382 -2.7e-05" quat="0.524056 0.524056 0.474727 0.474727" mass="0.08224" diaginertia="0.00139495 0.00103 0.000885049"/>
          <joint name="Right_Hand_j3" pos="0 0 0" axis="0 0 1" range="0 0.98506" actuatorfrcrange="-1000 1000"/>
          <geom type="mesh" contype="0" conaffinity="0" group="1" density="0" mesh="d12"/>
          <geom type="mesh" mesh="d12"/>
          <body name="Right_Hand_c" pos="0.03 0 0">
            <inertial pos="0.113729 0.01094 0" quat="0 0.707107 0 0.707107" mass="0.06198" diaginertia="0.00052 0.00051 0.00025"/>
            <joint name="Right_Hand_j4" pos="0 0 0" axis="0 0 1" range="0 1.406" actuatorfrcrange="-1000 1000"/>
            <geom type="mesh" contype="0" conaffinity="0" group="1" density="0" mesh="d13"/>
            <geom type="mesh" mesh="d13"/>
          </body>
        </body>
      </body>
    </body>
    <body name="Right_Hand_virtual_l" pos="-0.025 -0.01313 0.11" quat="0.500048 0.499952 -0.5 0.5">
      <inertial pos="0.003634 0.000206 -0.09885" quat="0.69352 0.69352 0.13795 -0.13795" mass="0.02383" diaginertia="0.000214142 0.000185858 0.00011"/>
      <joint name="Right_Hand_index_spread" pos="0 0 0" axis="0 0 1" range="0 0.28833" actuatorfrcrange="-1000 1000"/>
      <geom pos="0 0 0.01321" quat="1 0 0 0" type="mesh" contype="0" conaffinity="0" group="1" density="0" mesh="f10"/>
      <geom pos="0 0 0.01321" quat="1 0 0 0" type="mesh" mesh="f10"/>
      <body name="Right_Hand_l" quat="0.707141 -0.707073 0 0">
        <inertial pos="0.261673 0.003521 0" quat="-0.00373415 0.707097 0.00373415 0.707097" mass="0.13003" diaginertia="0.00344 0.00335032 0.000509683"/>
        <joint name="Right_Hand_Index_Finger_Proximal" pos="0 0 0" axis="0 0 1" range="0 0.79849" actuatorfrcrange="-1000 1000"/>
        <geom type="mesh" contype="0" conaffinity="0" group="1" density="0" mesh="f11"/>
        <geom type="mesh" mesh="f11"/>
        <body name="Right_Hand_p" pos="0.04804 0 0">
          <inertial pos="0.1384 -0.004609 0" quat="0.5 0.5 0.5 0.5" mass="0.03264" diaginertia="0.00031 0.00024 0.00016"/>
          <joint name="Right_Hand_Index_Finger_Distal" pos="0 0 0" axis="0 0 1" range="0 1.334" actuatorfrcrange="-1000 1000"/>
          <geom type="mesh" contype="0" conaffinity="0" group="1" density="0" mesh="f12"/>
          <geom type="mesh" mesh="f12"/>
          <body name="Right_Hand_t" pos="0.026 0 0">
            <inertial pos="0.102924 0.000592 0" quat="0.468459 0.468459 0.529666 0.529666" mass="0.0324" diaginertia="0.000171231 0.00017 8.87689e-05"/>
            <joint name="Right_Hand_j14" pos="0 0 0" axis="0 0 1" range="0 1.394" actuatorfrcrange="-1000 1000"/>
            <geom type="mesh" contype="0" conaffinity="0" group="1" density="0" mesh="f13"/>
            <geom type="mesh" mesh="f13"/>
          </body>
        </body>
      </body>
    </body>
    <body name="Right_Hand_k" pos="0 -0.01313 0.11" quat="0.707107 -3.40567e-05 -0.707107 3.40567e-05">
      <inertial pos="0.271122 0.00413 0" quat="-0.003335 0.707099 0.003335 0.707099" mass="0.13474" diaginertia="0.0038 0.00370028 0.000519717"/>
      <joint name="Right_Hand_Middle_Finger_Proximal" pos="0 0 0" axis="0 0 1" range="0 0.79849" actuatorfrcrange="-1000 1000"/>
      <geom type="mesh" contype="0" conaffinity="0" group="1" density="0" mesh="f21"/>
      <geom type="mesh" mesh="f21"/>
      <body name="Right_Hand_o" pos="0.05004 0 0">
        <inertial pos="0.16683 -0.003774 0" quat="0.5 0.5 0.5 0.5" mass="0.0422" diaginertia="0.00047 0.0004 0.0002"/>
        <joint name="Right_Hand_Middle_Finger_Distal" pos="0 0 0" axis="0 0 1" range="0 1.334" actuatorfrcrange="-1000 1000"/>
        <geom type="mesh" contype="0" conaffinity="0" group="1" density="0" mesh="f22"/>
        <geom type="mesh" mesh="f22"/>
        <body name="Right_Hand_s" pos="0.032 0 0">
          <inertial pos="0.102794 0.00042 0" quat="0.468459 0.468459 0.529666 0.529666" mass="0.03239" diaginertia="0.000171231 0.00017 8.87689e-05"/>
          <joint name="Right_Hand_j15" pos="0 0 0" axis="0 0 1" range="0 1.334" actuatorfrcrange="-1000 1000"/>
          <geom type="mesh" contype="0" conaffinity="0" group="1" density="0" mesh="f23"/>
          <geom type="mesh" mesh="f23"/>
        </body>
      </body>
    </body>
    <body name="Right_Hand_virtual_i" pos="0.043755 -0.01313 0.0935" quat="0.500048 -0.5 -0.5 -0.499952">
      <inertial pos="0.003653 4.4e-05 0.100085" quat="0.69352 0.69352 -0.13795 0.13795" mass="0.02377" diaginertia="0.000214142 0.000185858 0.00011"/>
      <joint name="Right_Hand_Finger_Spread" pos="0 0 0" axis="0 0 1" range="0 0.5829" actuatorfrcrange="-1000 1000"/>
      <geom pos="0 0 -0.01321" quat="1 0 0 0" type="mesh" contype="0" conaffinity="0" group="1" density="0" mesh="f40"/>
      <geom pos="0 0 -0.01321" quat="1 0 0 0" type="mesh" mesh="f40"/>
      <body name="Right_Hand_i" quat="0.707141 0.707073 0 0">
        <inertial pos="0.232293 0.00622 0" quat="0.00793951 0.707062 -0.00793951 0.707062" mass="0.12544" diaginertia="0.00328 0.00316135 0.000488652"/>
        <joint name="Right_Hand_Pinky" pos="0 0 0" axis="0 0 1" range="0 0.98175" actuatorfrcrange="-1000 1000"/>
        <geom type="mesh" contype="0" conaffinity="0" group="1" density="0" mesh="f41"/>
        <geom type="mesh" mesh="f41"/>
        <body name="Right_Hand_m" pos="0.04454 0 0">
          <inertial pos="0.119665 -0.009328 0" quat="0.5 0.5 0.5 0.5" mass="0.02488" diaginertia="0.00023 0.00016 0.00013"/>
          <joint name="Right_Hand_j13" pos="0 0 0" axis="0 0 1" range="0 1.334" actuatorfrcrange="-1000 1000"/>
          <geom type="mesh" contype="0" conaffinity="0" group="1" density="0" mesh="f42"/>
          <geom type="mesh" mesh="f42"/>
          <body name="Right_Hand_q" pos="0.022 0 0">
            <inertial pos="0.102896 0.000307 0" quat="0.468459 0.468459 0.529666 0.529666" mass="0.03234" diaginertia="0.000171231 0.00017 8.87689e-05"/>
            <joint name="Right_Hand_j17" pos="0 0 0" axis="0 0 1" range="0 1.3971" actuatorfrcrange="-1000 1000"/>
            <geom type="mesh" contype="0" conaffinity="0" group="1" density="0" mesh="f43"/>
            <geom type="mesh" mesh="f43"/>
          </body>
        </body>
      </body>
    </body>
    <body name="Right_Hand_virtual_j" pos="0.022255 -0.01313 0.103" quat="0.500048 -0.5 -0.5 -0.499952">
      <inertial pos="0.003805 0.000386 0.100079" quat="0.69352 0.69352 -0.13795 0.13795" mass="0.02377" diaginertia="0.000214142 0.000185858 0.00011"/>
      <joint name="Right_Hand_ring_spread" pos="0 0 0" axis="0 0 1" range="0 0.28833" actuatorfrcrange="-1000 1000"/>
      <geom pos="0 0 -0.01321" quat="1 0 0 0" type="mesh" contype="0" conaffinity="0" group="1" density="0" mesh="f30"/>
      <geom pos="0 0 -0.01321" quat="1 0 0 0" type="mesh" mesh="f30"/>
      <body name="Right_Hand_j" quat="0.707141 0.707073 0 0">
        <inertial pos="0.258283 -0.00154 0" quat="0.0178138 0.706882 -0.0178138 0.706882" mass="0.1377" diaginertia="0.00426 0.00411908 0.000540922"/>
        <joint name="Right_Hand_Ring_Finger" pos="0 0 0" axis="0 0 1" range="0 0.98175" actuatorfrcrange="-1000 1000"/>
        <geom type="mesh" contype="0" conaffinity="0" group="1" density="0" mesh="f31"/>
        <geom type="mesh" mesh="f31"/>
        <body name="Right_Hand_n" pos="0.05004 0 0">
          <inertial pos="0.166851 -0.00362 0" quat="0.5 0.5 0.5 0.5" mass="0.04207" diaginertia="0.00047 0.0004 0.00019"/>
          <joint name="Right_Hand_j12" pos="0 0 0" axis="0 0 1" range="0 1.334" actuatorfrcrange="-1000 1000"/>
          <geom type="mesh" contype="0" conaffinity="0" group="1" density="0" mesh="f32"/>
          <geom type="mesh" mesh="f32"/>
          <body name="Right_Hand_r" pos="0.032 0 0">
            <inertial pos="0.102676 0.000301 0" quat="0.468459 0.468459 0.529666 0.529666" mass="0.03229" diaginertia="0.000171231 0.00017 8.87689e-05"/>
            <joint name="Right_Hand_j16" pos="0 0 0" axis="0 0 1" range="0 1.395" actuatorfrcrange="-1000 1000"/>
            <geom type="mesh" contype="0" conaffinity="0" group="1" density="0" mesh="f33"/>
            <geom type="mesh" mesh="f33"/>
          </body>
        </body>
      </body>
    </body>
  </worldbody>

  <!-- Keep the order of joint creation from above. That's crucial for equally indexing joint state vectors and actuator torque vectors in the solver -->
  <actuator>
    <position name="Right_Hand_Thumb_Opposition"       ctrlrange="-3.141 3.141" kp="1000" dampratio="1" joint="Right_Hand_Thumb_Opposition"      />
    <position name="Right_Hand_Thumb_Flexion"          ctrlrange="-3.141 3.141" kp="1000" dampratio="1" joint="Right_Hand_Thumb_Flexion"         />
    <position name="Right_Hand_j3"                     ctrlrange="-3.141 3.141" kp="1000" dampratio="1" joint="Right_Hand_j3"                    />
    <position name="Right_Hand_j4"                     ctrlrange="-3.141 3.141" kp="1000" dampratio="1" joint="Right_Hand_j4"                    />
    <position name="Right_Hand_index_spread"           ctrlrange="-3.141 3.141" kp="1000" dampratio="1" joint="Right_Hand_index_spread"          />
    <position name="Right_Hand_Index_Finger_Proximal"  ctrlrange="-3.141 3.141" kp="1000" dampratio="1" joint="Right_Hand_Index_Finger_Proximal" />
    <position name="Right_Hand_Index_Finger_Distal"    ctrlrange="-3.141 3.141" kp="1000" dampratio="1" joint="Right_Hand_Index_Finger_Distal"   />
    <position name="Right_Hand_j14"                    ctrlrange="-3.141 3.141" kp="1000" dampratio="1" joint="Right_Hand_j14"                   />
    <position name="Right_Hand_Middle_Finger_Proximal" ctrlrange="-3.141 3.141" kp="1000" dampratio="1" joint="Right_Hand_Middle_Finger_Proximal"/>
    <position name="Right_Hand_Middle_Finger_Distal"   ctrlrange="-3.141 3.141" kp="1000" dampratio="1" joint="Right_Hand_Middle_Finger_Distal"  />
    <position name="Right_Hand_j15"                    ctrlrange="-3.141 3.141" kp="1000" dampratio="1" joint="Right_Hand_j15"                   />
    <position name="Right_Hand_Finger_Spread"          ctrlrange="-3.141 3.141" kp="1000" dampratio="1" joint="Right_Hand_Finger_Spread"         />
    <position name="Right_Hand_Pinky"                  ctrlrange="-3.141 3.141" kp="1000" dampratio="1" joint="Right_Hand_Pinky"                 />
    <position name="Right_Hand_j13"                    ctrlrange="-3.141 3.141" kp="1000" dampratio="1" joint="Right_Hand_j13"                   />
    <position name="Right_Hand_j17"                    ctrlrange="-3.141 3.141" kp="1000" dampratio="1" joint="Right_Hand_j17"                   />
    <position name="Right_Hand_ring_spread"            ctrlrange="-3.141 3.141" kp="1000" dampratio="1" joint="Right_Hand_ring_spread"           />
    <position name="Right_Hand_Ring_Finger"            ctrlrange="-3.141 3.141" kp="1000" dampratio="1" joint="Right_Hand_Ring_Finger"           />
    <position name="Right_Hand_j12"                    ctrlrange="-3.141 3.141" kp="1000" dampratio="1" joint="Right_Hand_j12"                   />
    <position name="Right_Hand_j16"                    ctrlrange="-3.141 3.141" kp="1000" dampratio="1" joint="Right_Hand_j16"                   />
  </actuator>

    <!-- Initial joint states for simulation -->
    <include file="initial_joint_states.xml"/>
</mujoco>
